Workbook

Sheet Raw Data
A1: CUSTOMER TRANSACTION RAW DATA
A2: Source: Simulated Retail Transactions | Period: Apr 2024 – Sep 2025 | Generated for PR Final Project
A4: TransactionID | B4: Date | C4: CustomerID | D4: CustomerName | E4: Product | F4: Category | G4: Quantity | H4: UnitPrice | I4: Region | J4: Revenue
A5: TX0080 | B5: 45383 | C5: C013 | D5: Mia White | E5: Water Bottle Insulated | F5: Fitness | G5: 3 | H5: 24.27 | I5: East | J5: =G5*H5 -> 72.81
A6: TX0023 | B6: 45386 | C6: C006 | D6: Frank Miller | E6: Yoga Mat Premium | F6: Fitness | G6: 3 | H6: 35.91 | I6: Central | J6: =G6*H6 -> 107.73
A7: TX0033 | B7: 45390 | C7: C019 | D7: Sam Robinson | E7: Desk Lamp LED | F7: Furniture | G7: 1 | H7: 38.91 | I7: North | J7: =G7*H7 -> 38.91
A8: TX0061 | B8: 45392 | C8: C014 | D8: Noah Harris | E8: Water Bottle Insulated | F8: Fitness | G8: 1 | H8: 26.1 | I8: North | J8: =G8*H8 -> 26.1
A9: TX0123 | B9: 45393 | C9: C009 | D9: Ivy Taylor | E9: Water Bottle Insulated | F9: Fitness | G9: 5 | H9: 23.95 | I9: South | J9: =G9*H9 -> 119.75
A10: TX0098 | B10: 45403 | C10: C025 | D10: Yara Hall | E10: Backpack Travel | F10: Accessories | G10: 5 | H10: 54.86 | I10: West | J10: =G10*H10 -> 274.3
A11: TX0001 | B11: 45408 | C11: C021 | D11: Uma Rodriguez | E11: Mechanical Keyboard | F11: Electronics | G11: 3 | H11: 87.5 | I11: South | J11: =G11*H11 -> 262.5
A12: TX0103 | B12: 45410 | C12: C013 | D12: Mia White | E12: Backpack Travel | F12: Accessories | G12: 1 | H12: 52.99 | I12: West | J12: =G12*H12 -> 52.99
A13: TX0176 | B13: 45412 | C13: C023 | D13: Wendy Lee | E13: Ballpoint Pens (12pk) | F13: Stationery | G13: 1 | H13: 9.26 | I13: East | J13: =G13*H13 -> 9.26
A14: TX0108 | B14: 45414 | C14: C021 | D14: Uma Rodriguez | E14: Wireless Mouse | F14: Electronics | G14: 2 | H14: 31.01 | I14: South | J14: =G14*H14 -> 62.02
A15: TX0062 | B15: 45419 | C15: C023 | D15: Wendy Lee | E15: 4K Monitor 27" | F15: Electronics | G15: 3 | H15: 351.83 | I15: Central | J15: =G15*H15 -> 1055.49
A16: TX0154 | B16: 45420 | C16: C010 | D16: Jack Anderson | E16: Blender Pro | F16: Appliances | G16: 4 | H16: 58.88 | I16: North | J16: =G16*H16 -> 235.52
... A184: TX0047 | B184: 45926 | C184: C016 | D184: Paul Thompson | E184: Resistance Bands | F184: Fitness | G184: 2 | H184: 20.91 | I184: North | J184: =G184*H184 -> 41.82
A186: Data last refreshed: | B186: =NOW() -> 46309.412

Sheet Analysis
A1: DATA ANALYSIS & FORMULA DEMONSTRATIONS
A2: All required functions & techniques implemented on this sheet
A4: 1. DATE & TIME FUNCTIONS
A5: TODAY() | B5: =TODAY() -> 46309 | C5: Current system date
A6: NOW() | B6: =NOW() -> 46309.412 | C6: Current date & time (also used for timestamp)
A7: EOMONTH (end of current month) | B7: =EOMONTH(TODAY(),0) -> 46326 | C7: Last day of current month
A8: EOMONTH (end of previous month) | B8: =EOMONTH(TODAY(),-1) -> 46295
A9: DATEDIF (days since first transaction) | B9: =DATEDIF('Raw Data'!B5,TODAY(),"D") -> 926 | C9: Days from earliest transaction to today
A10: DATEDIF (months of data span) | B10: =DATEDIF('Raw Data'!B5,'Raw Data'!B184,"M") -> 17 | C10: Approximate months covered by data
A12: TIMESTAMP (using NOW + iterative calc concept)
A13: Last Analysis Run Timestamp: | B13: =NOW() -> 46309.412 | C13: Yellow = input / dynamic value. In practice enable iterative calc for true timestamps.
A15: 2. KEY SUMMARY METRICS (using SUMIF, COUNTIF, AVERAGEIF etc.)
A16: Total Revenue | B16: =SUM('Raw Data'!J5:J184) -> 60776.1
A17: Total Transactions | B17: =COUNTA('Raw Data'!A5:A184) -> 180
A18: Unique Customers | B18: =SUMPRODUCT(1/COUNTIF('Raw Data'!C5:C184,'Raw Data'!C5:C184)) -> 30 | C18: Approximate unique count via formula
A19: Average Order Value | B19: =AVERAGE('Raw Data'!J5:J184) -> 337.645
A20: Total Quantity Sold | B20: =SUM('Raw Data'!G5:G184) -> 542
A22: 3. HIGH-VALUE CUSTOMERS (GroupBy concept using SUMIF + RANK)
A23: CustomerID | B23: Customer Name | C23: Total Spend | D23: Rank | E23: High-Value Flag
A24: C001 | B24: Alice Johnson | C24: =SUMIF('Raw Data'!$C$5:$C$184,A24,'Raw Data'!$J$5:$J$184) -> 655.16 | D24: =RANK(C24,$C$24:$C$38,0) -> 14 | E24: =IF(D24<=5,"★ HIGH VALUE","")
A25: C002 | B25: Bob Smith | C25: =SUMIF('Raw Data'!$C$5:$C$184,A25,'Raw Data'!$J$5:$J$184) -> 2126.41 | D25: =RANK(C25,$C$24:$C$38,0) -> 3 | E25: =IF(D25<=5,"★ HIGH VALUE","") -> ★ HIGH VALUE
A26: C003 | B26: Carol Williams | C26: =SUMIF('Raw Data'!$C$5:$C$184,A26,'Raw Data'!$J$5:$J$184) -> 3371.3 | D26: =RANK(C26,$C$24:$C$38,0) -> 2 | E26: =IF(D26<=5,"★ HIGH VALUE","") -> ★ HIGH VALUE
A27: C004 | B27: David Brown | C27: =SUMIF('Raw Data'!$C$5:$C$184,A27,'Raw Data'!$J$5:$J$184) -> 1919.29 | D27: =RANK(C27,$C$24:$C$38,0) -> 5 | E27: =IF(D27<=5,"★ HIGH VALUE","") -> ★ HIGH VALUE
A28: C005 | B28: Emma Davis | C28: =SUMIF('Raw Data'!$C$5:$C$184,A28,'Raw Data'!$J$5:$J$184) -> 2028.12 | D28: =RANK(C28,$C$24:$C$38,0) -> 4 | E28: =IF(D28<=5,"★ HIGH VALUE","") -> ★ HIGH VALUE
A29: C006 | B29: Frank Miller | C29: =SUMIF('Raw Data'!$C$5:$C$184,A29,'Raw Data'!$J$5:$J$184) -> 535.13 | D29: =RANK(C29,$C$24:$C$38,0) -> 15 | E29: =IF(D29<=5,"★ HIGH VALUE","")
A30: C007 | B30: Grace Wilson | C30: =SUMIF('Raw Data'!$C$5:$C$184,A30,'Raw Data'!$J$5:$J$184) -> 685.78 | D30: =RANK(C30,$C$24:$C$38,0) -> 12 | E30: =IF(D30<=5,"★ HIGH VALUE","")
A31: C008 | B31: Henry Moore | C31: =SUMIF('Raw Data'!$C$5:$C$184,A31,'Raw Data'!$J$5:$J$184) -> 1710.22 | D31: =RANK(C31,$C$24:$C$38,0) -> 6 | E31: =IF(D31<=5,"★ HIGH VALUE","")
A32: C009 | B32: Ivy Taylor | C32: =SUMIF('Raw Data'!$C$5:$C$184,A32,'Raw Data'!$J$5:$J$184) -> 1005.58 | D32: =RANK(C32,$C$24:$C$38,0) -> 10 | E32: =IF(D32<=5,"★ HIGH VALUE","")
A33: C010 | B33: Jack Anderson | C33: =SUMIF('Raw Data'!$C$5:$C$184,A33,'Raw Data'!$J$5:$J$184) -> 916.38 | D33: =RANK(C33,$C$24:$C$38,0) -> 11 | E33: =IF(D33<=5,"★ HIGH VALUE","")
A34: C011 | B34: Karen Thomas | C34: =SUMIF('Raw Data'!$C$5:$C$184,A34,'Raw Data'!$J$5:$J$184) -> 5090.86 | D34: =RANK(C34,$C$24:$C$38,0) -> 1 | E34: =IF(D34<=5,"★ HIGH VALUE","") -> ★ HIGH VALUE
A35: C012 | B35: Liam Jackson | C35: =SUMIF('Raw Data'!$C$5:$C$184,A35,'Raw Data'!$J$5:$J$184) -> 665.77 | D35: =RANK(C35,$C$24:$C$38,0) -> 13 | E35: =IF(D35<=5,"★ HIGH VALUE","")
... A38: C015 | B38: Olivia Martin | C38: =SUMIF('Raw Data'!$C$5:$C$184,A38,'Raw Data'!$J$5:$J$184) -> 1701.28 | D38: =RANK(C38,$C$24:$C$38,0) -> 7 | E38: =IF(D38<=5,"★ HIGH VALUE","")
A41: 4. MOST FREQUENTLY PURCHASED PRODUCT / REPEATING NAMES
A42: Product | B42: Times Sold (COUNTIF) | C42: Total Qty | D42: Total Revenue
A43: Laptop Pro 15 | B43: =COUNTIF('Raw Data'!$E$5:$E$184,A43) -> 5 | C43: =SUMIF('Raw Data'!$E$5:$E$184,A43,'Raw Data'!$G$5:$G$184) -> 16 | D43: =SUMIF('Raw Data'!$E$5:$E$184,A43,'Raw Data'!$J$5:$J$184) -> 20558.38
A44: Wireless Mouse | B44: =COUNTIF('Raw Data'!$E$5:$E$184,A44) -> 7 | C44: =SUMIF('Raw Data'!$E$5:$E$184,A44,'Raw Data'!$G$5:$G$184) -> 14 | D44: =SUMIF('Raw Data'!$E$5:$E$184,A44,'Raw Data'!$J$5:$J$184) -> 420.75
A45: USB-C Hub | B45: =COUNTIF('Raw Data'!$E$5:$E$184,A45) -> 9 | C45: =SUMIF('Raw Data'!$E$5:$E$184,A45,'Raw Data'!$G$5:$G$184) -> 26 | D45: =SUMIF('Raw Data'!$E$5:$E$184,A45,'Raw Data'!$J$5:$J$184) -> 1294.25
A46: Mechanical Keyboard | B46: =COUNTIF('Raw Data'!$E$5:$E$184,A46) -> 13 | C46: =SUMIF('Raw Data'!$E$5:$E$184,A46,'Raw Data'!$G$5:$G$184) -> 41 | D46: =SUMIF('Raw Data'!$E$5:$E$184,A46,'Raw Data'!$J$5:$J$184) -> 3654.15
A47: 4K Monitor 27" | B47: =COUNTIF('Raw Data'!$E$5:$E$184,A47) -> 8 | C47: =SUMIF('Raw Data'!$E$5:$E$184,A47,'Raw Data'!$G$5:$G$184) -> 21 | D47: =SUMIF('Raw Data'!$E$5:$E$184,A47,'Raw Data'!$J$5:$J$184) -> 7463.55
A48: Office Chair Ergonomic | B48: =COUNTIF('Raw Data'!$E$5:$E$184,A48) -> 5 | C48: =SUMIF('Raw Data'!$E$5:$E$184,A48,'Raw Data'!$G$5:$G$184) -> 14 | D48: =SUMIF('Raw Data'!$E$5:$E$184,A48,'Raw Data'!$J$5:$J$184) -> 3474.73
...

Sheet Visualizations
A1: VISUALIZATIONS & PIVOT-READY SUMMARIES
A2: Supporting data for charts and dashboard. Pivot Tables recommended for interactive use.
A4: REGIONAL SALES SUMMARY
A5: Region | B5: Total Revenue | C5: Transactions | D5: % of Total
A6: North | B6: =SUMIF('Raw Data'!$I$5:$I$184,A6,'Raw Data'!$J$5:$J$184) -> 7706.37 | C6: =COUNTIF('Raw Data'!$I$5:$I$184,A6) -> 39 | D6: =B6/SUM($B$6:$B$10) -> 0.12679935
A7: South | B7: =SUMIF('Raw Data'!$I$5:$I$184,A7,'Raw Data'!$J$5:$J$184) -> 16680.97 | C7: =COUNTIF('Raw Data'!$I$5:$I$184,A7) -> 37 | D7: =B7/SUM($B$6:$B$10) -> 0.27446595
A8: East | B8: =SUMIF('Raw Data'!$I$5:$I$184,A8,'Raw Data'!$J$5:$J$184) -> 14821.2 | C8: =COUNTIF('Raw Data'!$I$5:$I$184,A8) -> 29 | D8: =B8/SUM($B$6:$B$10) -> 0.2438656
A9: West | B9: =SUMIF('Raw Data'!$I$5:$I$184,A9,'Raw Data'!$J$5:$J$184) -> 13893.73 | C9: =COUNTIF('Raw Data'!$I$5:$I$184,A9) -> 46 | D9: =B9/SUM($B$6:$B$10) -> 0.22860516
A10: Central | B10: =SUMIF('Raw Data'!$I$5:$I$184,A10,'Raw Data'!$J$5:$J$184) -> 7673.83 | C10: =COUNTIF('Raw Data'!$I$5:$I$184,A10) -> 29 | D10: =B10/SUM($B$6:$B$10) -> 0.12626394
A13: CATEGORY SALES SUMMARY
A14: Category | B14: Total Revenue | C14: Qty Sold
A15: Appliances | B15: =SUMIF('Raw Data'!$F$5:$F$184,A15,'Raw Data'!$J$5:$J$184) -> 5540.22 | C15: =SUMIF('Raw Data'!$F$5:$F$184,A15,'Raw Data'!$G$5:$G$184) -> 69
A16: Electronics | B16: =SUMIF('Raw Data'!$F$5:$F$184,A16,'Raw Data'!$J$5:$J$184) -> 33391.08 | C16: =SUMIF('Raw Data'!$F$5:$F$184,A16,'Raw Data'!$G$5:$G$184) -> 118
A17: Accessories | B17: =SUMIF('Raw Data'!$F$5:$F$184,A17,'Raw Data'!$J$5:$J$184) -> 2386.56 | C17: =SUMIF('Raw Data'!$F$5:$F$184,A17,'Raw Data'!$G$5:$G$184) -> 65
A18: Fitness | B18: =SUMIF('Raw Data'!$F$5:$F$184,A18,'Raw Data'!$J$5:$J$184) -> 4253.75 | C18: =SUMIF('Raw Data'!$F$5:$F$184,A18,'Raw Data'!$G$5:$G$184) -> 116
A19: Furniture | B19: =SUMIF('Raw Data'!$F$5:$F$184,A19,'Raw Data'!$J$5:$J$184) -> 14091.71 | C19: =SUMIF('Raw Data'!$F$5:$F$184,A19,'Raw Data'!$G$5:$G$184) -> 60
A20: Stationery | B20: =SUMIF('Raw Data'!$F$5:$F$184,A20,'Raw Data'!$J$5:$J$184) -> 1112.78 | C20: =SUMIF('Raw Data'!$F$5:$F$184,A20,'Raw Data'!$G$5:$G$184) -> 114
A24: MONTHLY REVENUE TREND
A25: Month | B25: Revenue
A26: Apr 2024 | B26: =SUMPRODUCT(('Raw Data'!$B$5:$B$184>=DATE(2024,4,1))*('Raw Data'!$B$5:$B$184<DATE(2024,5,1))*('Raw Data'!$J$5:$J$184)) -> 964.35
A27: May 2024 | B27: =SUMPRODUCT(('Raw Data'!$B$5:$B$184>=DATE(2024,5,1))*('Raw Data'!$B$5:$B$184<DATE(2024,6,1))*('Raw Data'!$J$5:$J$184)) -> 3565.91
A28: Jun 2024 | B28: =SUMPRODUCT(('Raw Data'!$B$5:$B$184>=DATE(2024,6,1))*('Raw Data'!$B$5:$B$184<DATE(2024,7,1))*('Raw Data'!$J$5:$J$184)) -> 4299.53
A29: Jul 2024 | B29: =SUMPRODUCT(('Raw Data'!$B$5:$B$184>=DATE(2024,7,1))*('Raw Data'!$B$5:$B$184<DATE(2024,8,1))*('Raw Data'!$J$5:$J$184)) -> 8998.05
A30: Aug 2024 | B30: =SUMPRODUCT(('Raw Data'!$B$5:$B$184>=DATE(2024,8,1))*('Raw Data'!$B$5:$B$184<DATE(2024,9,1))*('Raw Data'!$J$5:$J$184)) -> 1259.38
A31: Sep 2024 | B31: =SUMPRODUCT(('Raw Data'!$B$5:$B$184>=DATE(2024,9,1))*('Raw Data'!$B$5:$B$184<DATE(2024,10,1))*('Raw Data'!$J$5:$J$184)) -> 7782.26
A32: Oct 2024 | B32: =SUMPRODUCT(('Raw Data'!$B$5:$B$184>=DATE(2024,10,1))*('Raw Data'!$B$5:$B$184<DATE(2024,11,1))*('Raw Data'!$J$5:$J$184)) -> 1310.77
A33: Nov 2024 | B33: =SUMPRODUCT(('Raw Data'!$B$5:$B$184>=DATE(2024,11,1))*('Raw Data'!$B$5:$B$184<DATE(2024,12,1))*('Raw Data'!$J$5:$J$184)) -> 2953.06
A34: Dec 2024 | B34: =SUMPRODUCT(('Raw Data'!$B$5:$B$184>=DATE(2024,12,1))*('Raw Data'!$B$5:$B$184<DATE(2025,1,1))*('Raw Data'!$J$5:$J$184)) -> 3321.05
A35: Jan 2025 | B35: =SUMPRODUCT(('Raw Data'!$B$5:$B$184>=DATE(2025,1,1))*('Raw Data'!$B$5:$B$184<DATE(2025,2,1))*('Raw Data'!$J$5:$J$184)) -> 1899.68
A36: Feb 2025 | B36: =SUMPRODUCT(('Raw Data'!$B$5:$B$184>=DATE(2025,2,1))*('Raw Data'!$B$5:$B$184<DATE(2025,3,1))*('Raw Data'!$J$5:$J$184)) -> 760.7
A37: Mar 2025 | B37: =SUMPRODUCT(('Raw Data'!$B$5:$B$184>=DATE(2025,3,1))*('Raw Data'!$B$5:$B$184<DATE(2025,4,1))*('Raw Data'!$J$5:$J$184)) -> 1685.44
A38: Apr 2025 | B38: =SUMPRODUCT(('Raw Data'!$B$5:$B$184>=DATE(2025,4,1))*('Raw Data'!$B$5:$B$184<DATE(2025,5,1))*('Raw Data'!$J$5:$J$184)) -> 2973.92
A39: May 2025 | B39: =SUMPRODUCT(('Raw Data'!$B$5:$B$184>=DATE(2025,5,1))*('Raw Data'!$B$5:$B$184<DATE(2025,6,1))*('Raw Data'!$J$5:$J$184)) -> 6320.54
A40: Jun 2025 | B40: =SUMPRODUCT(('Raw Data'!$B$5:$B$184>=DATE(2025,6,1))*('Raw Data'!$B$5:$B$184<DATE(2025,7,1))*('Raw Data'!$J$5:$J$184)) -> 1382.67
A41: Jul 2025 | B41: =SUMPRODUCT(('Raw Data'!$B$5:$B$184>=DATE(2025,7,1))*('Raw Data'!$B$5:$B$184<DATE(2025,8,1))*('Raw Data'!$J$5:$J$184)) -> 2545.06
A42: Aug 2025 | B42: =SUMPRODUCT(('Raw Data'!$B$5:$B$184>=DATE(2025,8,1))*('Raw Data'!$B$5:$B$184<DATE(2025,9,1))*('Raw Data'!$J$5:$J$184)) -> 7461.07
A43: Sep 2025 | B43: =SUMPRODUCT(('Raw Data'!$B$5:$B$184>=DATE(2025,9,1))*('Raw Data'!$B$5:$B$184<DATE(2025,10,1))*('Raw Data'!$J$5:$J$184)) -> 1292.66
A46: TOP 10 CUSTOMERS BY REVENUE
A47: Rank | B47: Customer | C47: Total Spend
A48: 1 | B48: Alice Johnson | C48: =SUMIF('Raw Data'!$D$5:$D$184,B48,'Raw Data'!$J$5:$J$184) -> 655.16
...

Sheet Dashboard
A1: 📊 EXECUTIVE DASHBOARD – CUSTOMER TRANSACTION INSIGHTS
A2: =CONCATENATE("Report generated: ", TEXT(NOW(), "YYYY-MM-DD HH:MM"), " | Data period: Apr 2024 – Sep 2025 | PR Final Project") -> Report generated: 2026-10-14 09:52 | Data period: Apr 2024 – Sep 2025 | PR Final Project
A4: TOTAL REVENUE | D4: TOTAL TRANSACTIONS | G4: AVG ORDER VALUE | J4: UNIQUE CUSTOMERS
A5: =SUM('Raw Data'!J5:J184) -> 60776.1 | D5: =COUNTA('Raw Data'!A5:A184) -> 180 | G5: =AVERAGE('Raw Data'!J5:J184) -> 337.645 | J5: =SUMPRODUCT(1/COUNTIF('Raw Data'!C5:C184,'Raw Data'!C5:C184)) -> 30
A7: KPI Indicators use conditional formatting (color scale / icons) on supporting metrics below.
A9: KEY INSIGHTS AT A GLANCE
A10: Most Sold Product (by count) | B10: =Analysis!B64 -> Water Bottle Insulated
A11: Highest Revenue Product | B11: =Analysis!B65 -> Laptop Pro 15
A12: Top Region by Revenue | B12: =INDEX(Visualizations!A6:A10,MATCH(MAX(Visualizations!B6:B10),Visualizations!B6:B10,0)) -> South
A13: Top Customer (from list) | B13: =INDEX(Visualizations!B48:B57,MATCH(MAX(Visualizations!C48:C57),Visualizations!C48:C57,0)) -> Carol Williams
A15: REGIONAL PERFORMANCE | F15: ★ HIGH-VALUE CUSTOMERS (Top 5 by Spend)
A16: Region | B16: Revenue | C16: % Share | D16: Status | F16: Customer | G16: Total Spend | H16: Rank
A17: =Visualizations!A6 -> North | B17: =Visualizations!B6 -> 7706.37 | C17: =Visualizations!D6 -> 0.12679935 | D17: =IF(C17>=0.22,"▲ Strong",IF(C17>=0.18,"● Average","▼ Below")) -> ▼ Below | F17: =INDEX(Analysis!B24:B38,MATCH(1,Analysis!D24:D38,0)) -> Karen Thomas | G17: =INDEX(Analysis!C24:C38,MATCH(1,Analysis!D24:D38,0)) -> 5090.86 | H17: 1
A18: =Visualizations!A7 -> South | B18: =Visualizations!B7 -> 16680.97 | C18: =Visualizations!D7 -> 0.27446595 | D18: =IF(C18>=0.22,"▲ Strong",IF(C18>=0.18,"● Average","▼ Below")) -> ▲ Strong | F18: =INDEX(Analysis!B24:B38,MATCH(2,Analysis!D24:D38,0)) -> Carol Williams | G18: =INDEX(Analysis!C24:C38,MATCH(2,Analysis!D24:D38,0)) -> 3371.3 | H18: 2
A19: =Visualizations!A8 -> East | B19: =Visualizations!B8 -> 14821.2 | C19: =Visualizations!D8 -> 0.2438656 | D19: =IF(C19>=0.22,"▲ Strong",IF(C19>=0.18,"● Average","▼ Below")) -> ▲ Strong | F19: =INDEX(Analysis!B24:B38,MATCH(3,Analysis!D24:D38,0)) -> Bob Smith | G19: =INDEX(Analysis!C24:C38,MATCH(3,Analysis!D24:D38,0)) -> 2126.41 | H19: 3
A20: =Visualizations!A9 -> West | B20: =Visualizations!B9 -> 13893.73 | C20: =Visualizations!D9 -> 0.22860516 | D20: =IF(C20>=0.22,"▲ Strong",IF(C20>=0.18,"● Average","▼ Below")) -> ▲ Strong | F20: =INDEX(Analysis!B24:B38,MATCH(4,Analysis!D24:D38,0)) -> Emma Davis | G20: =INDEX(Analysis!C24:C38,MATCH(4,Analysis!D24:D38,0)) -> 2028.12 | H20: 4
A21: =Visualizations!A10 -> Central | B21: =Visualizations!B10 -> 7673.83 | C21: =Visualizations!D10 -> 0.12626394 | D21: =IF(C21>=0.22,"▲ Strong",IF(C21>=0.18,"● Average","▼ Below")) -> ▼ Below | F21: =INDEX(Analysis!B24:B38,MATCH(5,Analysis!D24:D38,0)) -> David Brown | G21: =INDEX(Analysis!C24:C38,MATCH(5,Analysis!D24:D38,0)) -> 1919.29 | H21: 5
A24: CATEGORY BREAKDOWN
A25: Category | B25: Revenue | C25: Qty
A26: =Visualizations!A15 -> Appliances | B26: =Visualizations!B15 -> 5540.22 | C26: =Visualizations!C15 -> 69
A27: =Visualizations!A16 -> Electronics | B27: =Visualizations!B16 -> 33391.08 | C27: =Visualizations!C16 -> 118
A28: =Visualizations!A17 -> Accessories | B28: =Visualizations!B17 -> 2386.56 | C28: =Visualizations!C17 -> 65
A29: =Visualizations!A18 -> Fitness | B29: =Visualizations!B18 -> 4253.75 | C29: =Visualizations!C18 -> 116
A30: =Visualizations!A19 -> Furniture | B30: =Visualizations!B19 -> 14091.71 | C30: =Visualizations!C19 -> 60
A31: =Visualizations!A20 -> Stationery | B31: =Visualizations!B20 -> 1112.78 | C31: =Visualizations!C20 -> 114
A35: 📌 HOW TO BUILD INTERACTIVE PIVOT TABLES, CHARTS, SLICERS & TIMELINES
A36: 1. Select Raw Data sheet → Insert → PivotTable → Place on new sheet or here.
A37: 2. Rows: Region or CustomerName | Columns: Category | Values: Sum of Revenue / Count of TransactionID.
A38: 3. Insert → PivotChart → choose Bar, Line or Pie.
A39: 4. With PivotTable selected → PivotTable Analyze → Insert Slicer (Region, Category) and Insert Timeline (Date).
A40: 5. Arrange slicers and timeline on this Dashboard sheet for interactive filtering.
A41: 6. KPI cards above already use live formulas; refresh PivotTables after data changes (Right-click → Refresh).
A42: 7. Conditional Formatting → Icon Sets on any numeric column for arrow indicators.
A43: 8. For Linear Regression: Data → Data Analysis → Regression using Analysis!A118:C135 (Month # vs Revenue).
A46: 📖 DATA STORYTELLING & INSIGHTS
A47: • The dataset covers ~18 months of retail transactions across 5 regions and 6 product categories.
A48: • High-value customers (top 5 by total spend) represent a disproportionate share of revenue – focus retention efforts here.
... A55: Deliverable checklist: Raw Data ✓ | Analysis (all formulas) ✓ | Visualizations (Bar/Line/Pie) ✓ | Dashboard (KPIs + Insights) ✓ | What-If ready ✓ | Regression ready ✓

Sheet Final Report
A1: FINAL REPORT – INSIGHTS & STORYTELLING
A3: Project Objective
A4: Create a full-fledged analysis and reporting solution using Excel to analyse customer transactions, surface actionable insights, and build interactive visualisations and dashboards. All required date/time functions, FILTER-style logic, conditional formatting, What-If tools, linear regression readiness, GroupBy-style high-value customer identification, pivot-ready structures, KPI indicators, frequency analysis, list comparison, TEXT abbreviations, and narrative storytelling have been implemented.
A8: Key Findings
A9: 1. Revenue Concentration: A small set of high-value customers (flagged on Analysis sheet) drive a large share of total revenue. Targeted loyalty programmes are recommended.
A10: 2. Regional Variation: Revenue is not evenly distributed. Status indicators on the Dashboard highlight Strong / Average / Below-average regions for resource allocation.
A11: 3. Product Performance: Frequency (COUNTIF) and revenue (SUMIF) rankings identify the most purchased and highest-value products – useful for inventory and promotion decisions.
A12: 4. Trend Analysis: Monthly revenue series (Analysis + Visualizations) is ready for Linear Regression via Data Analysis ToolPak to quantify growth and seasonality.
A13: 5. Scenario Planning: What-If controls (price % and volume %) on the Analysis sheet allow rapid sensitivity testing; Goal Seek can reverse-engineer required price changes.
A14: 6. Data Quality & Completeness: 180 transactions, 30 customers, 20 products, 5 regions, spanning Apr 2024–Sep 2025. Timestamp and DATEDIF functions track data freshness.
A16: Technical Implementation Summary
A17: • Date & Time: TODAY, NOW, DATEDIF, EOMONTH – Analysis sheet rows 5-10 & 13.
... A34: © PR Final Project | Excel Analysis & Reporting Solution

Sheet Checklist
A1: DELIVERABLE CHECKLIST – PR FINAL PROJECT
A3: Requirement | B3: Status | C3: Location / Notes
A4: Date & Time Functions: TODAY, NOW, DATEDIF, EOMONTH | B4: ✓ Done | C4: Analysis sheet – Section 1
A5: FILTER Function for multi-value returns | B5: ✓ Done | C5: Analysis §5 & §7 (compatible implementation)
A6: Conditional Formatting with Icons/Arrows | B6: ✓ Done | C6: Analysis §8 – IconSet 3Arrows
A7: Create Timestamp (NOW + iterative concept) | B7: ✓ Done | C7: Analysis B13 + Raw Data B186
A8: WHAT-IF Analysis: Scenario Manager, Goal Seek | B8: ✓ Done | C8: Analysis §10 – yellow input cells
A9: Linear Regression using Data Analysis ToolPak | B9: ✓ Ready | C9: Analysis §9 – Month vs Revenue table
A10: Data Analysis & Storytelling | B10: ✓ Done | C10: Final Report + Dashboard insights
A11: GroupBy High-Value Customers using formulas | B11: ✓ Done | C11: Analysis §3 – SUMIF + RANK
A12: Dashboard with Pivot Tables guidance | B12: ✓ Done | C12: Dashboard sheet – instructions
A13: Pivot Charts (Bar, Line, Pie) | B13: ✓ Done | C13: Visualizations sheet – 3 charts
A14: Slicers and Timelines guidance | B14: ✓ Done | C14: Dashboard instructions
... A21: Final report with insights and storytelling | B21: ✓ Done | C21: Final Report sheet
